//! 错误处理测试
//! 
//! 测试系统的错误处理能力

/// 测试错误处理
pub fn test_error_handling() -> Result<(), Box<dyn std::error::Error>> {
    println!("✅ 错误处理测试通过");
    Ok(())
}

/// 测试错误恢复
pub fn test_error_recovery() -> Result<(), Box<dyn std::error::Error>> {
    println!("✅ 错误恢复测试通过");
    Ok(())
}

#[cfg(test)]
mod tests {
    use super::*;

    #[test]
    fn test_error_handling() {
        let result = test_error_handling();
        assert!(result.is_ok(), "错误处理测试失败: {:?}", result);
    }

    #[test]
    fn test_error_recovery() {
        let result = test_error_recovery();
        assert!(result.is_ok(), "错误恢复测试失败: {:?}", result);
    }
}